Workbook

Sheet Dell's Financial Statements
A1: Financial Statement for: DELL TECHNOLOGIES INC | I1: Unlevered net income = (Revenues - Costs - Depreciation) * (1 – tax rate)
A2: Fiscal Years: 2021 to 2024
B3: 2021 | C3: =B3+1 -> 2022 | D3: =C3+1 -> 2023 | E3: =D3+1 -> 2024 | I3: 2021 | J3: =I3+1 -> 2022 | K3: =J3+1 -> 2023 | L3: =K3+1 -> 2024
H4: Revenues | I4: 101197 | J4: 102301 | K4: 88425 | L4: 95567
A5: BALANCE SHEET | H5: COGS | I5: 76802 | J5: 76907 | K5: 64655 | L5: 71468
A6: ASSETS | H6: SG&A | I6: 15916 | J6: 15918 | K6: 14596 | L6: 14046
A7: Cash and Short-Term Investments | B7: 10011 | C7: 8879 | D7: 7502 | E7: 3756 | H7: Depreciation & Amortization | I7: 3547 | J7: 3156 | K7: 3303 | L7: 3123
A8: Cash | B8: 9477 | C8: 8607 | D8: 7366 | E8: 3633 | H8: Tax Rate | I8: 0.21 | J8: 0.21 | K8: 0.21 | L8: 0.21
A9: Short-Term Investments | B9: 534 | C9: 272 | D9: 136 | E9: 123
A10: Receivables | B10: 18132 | C10: 18141 | D10: 13986 | E10: 15602 | H10: Unlevered Net Income | I10: =(I4-I5-I6-I7)*(1-I8) -> 3896.28 | J10: =(J4-J5-J6-J7)*(1-J8) -> 4992.8 | K10: =(K4-K5-K6-K7)*(1-K8) -> 4638.09 | L10: =(L4-L5-L6-L7)*(1-L8) -> 5474.7
A11: Receivables - Trade | B11: 18001 | C11: 17763 | D11: 13986 | E11: 15602
A12: Income Tax Refund | B12: 0 | C12: 0 | D12: 0 | E12: 0 | H12: Operating Income Before Depreciation | I12: 8479 | J12: 9476 | K12: 9174 | L12: 10053
A13: Current Receivables - Other | B13: 131 | C13: 378 | D13: 0 | E13: 0
A14: Inventories - Total | B14: 5898 | C14: 4776 | D14: 3622 | E14: 6716 | H14: EBITDA/Sales Profit Margin | I14: =I12/I4 -> 0.083787069 | J14: =J12/J4 -> 0.092628616 | K14: =K12/K4 -> 0.10374894 | L14: =L12/L4 -> 0.10519322
A15: Inventories - Raw Materials | B15: 3653 | C15: 3225 | D15: 2321 | E15: 4432
A16: Inventories - Work in Process | B16: 855 | C16: 708 | D16: 607 | E16: 1128
A17: Inventories - Finished Goods | B17: 1390 | C17: 843 | D17: 694 | E17: 1156 | I17: Operating Cash Flow
A18: Inventories - Other | B18: 0 | C18: 0 | D18: 0 | E18: 0
A19: Current Assets - Other | B19: 10992 | C19: 10555 | D19: 10837 | E19: 10155 | H19: ( - ) Accounts Receivables | I19: 18132 | J19: 18141 | K19: 13986 | L19: 15602
A20: Prepaid Expense | B20: 886 | C20: 641 | D20: 589 | E20: 564 | H20: ∆ Accounts Receivables | J20: =J19-I19 -> 9 | K20: =K19-J19 -> -4155 | L20: =L19-K19 -> 1616
A21: Other Curr.Asst, Excl.Ppd.Exp. | B21: 10106 | C21: 9914 | D21: 10248 | E21: 9591 | H21: ( - ) Inventory | I21: 5898 | J21: 4776 | K21: 3622 | L21: 6716
A22: Current Assets - Total | B22: 45033 | C22: 42351 | D22: 35947 | E22: 36229 | H22: ∆ Inventory | J22: =J21-I21 -> -1122 | K22: =K21-J21 -> -1154 | L22: =L21-K21 -> 3094
A23: Prop.Plant & Equip.- Total (Net) | B23: 6286 | C23: 6934 | D23: 7139 | E23: 6996 | H23: ( + ) Accounts Payable | I23: 27143 | J23: 18598 | K23: 19389 | L23: 20832
A24: P.P.& E.- Total (Gross) | B24: 13177 | C24: 13817 | D24: 14324 | E24: 14756 | H24: ∆ Accounts Payable | J24: =J23-I23 -> -8545 | K24: =K23-J23 -> 791 | L24: =L23-K23 -> 1443
A25: Deprec.Depl.& Amort. | B25: 6891 | C25: 6883 | D25: 7185 | E25: 7760 | H25: ( + ) Net Income
A26: Invest. & Advances - Eq.Meth. | B26: 0 | C26: 0 | D26: 0 | E26: 0 | H26: ( + ) Depreciation | I26: =I7 -> 3547 | J26: =J7 -> 3156 | K26: =K7 -> 3303 | L26: =L7 -> 3123
A27: Invest. & Advances - Other | B27: 8071 | C27: 7596 | D27: 7193 | E27: 7423 | H27: ( - ) Capital Expenditures | I27: 2796 | J27: 3003 | K27: 2756 | L27: 2652
A28: Intangibles | B28: 27903 | C28: 26817 | D28: 26047 | E28: 24731 | H28: NWC | I28: =I19+I21-I23 -> -3113 | J28: =J19+J21-J23 -> 4319 | K28: =K19+K21-K23 -> -1781 | L28: =L19+L21-L23 -> 1486
A29: Assets - Other | B29: 5442 | C29: 5913 | D29: 5763 | E29: 4367 | H29: ∆NWC | J29: =J20+J22-J24 -> 7432 | K29: =K20+K22-K24 -> -6100 | L29: =L20+L22-L24 -> 3267
A30: Deferred Charges | B30: . | C30: . | D30: . | E30: .
A31: Other Asst., Excl.Def.Chg. | B31: 5442 | C31: 5913 | D31: 5763 | E31: 4367 | I31: Free Cash Flow
A32: Assets - Total | B32: 92735 | C32: 89611 | D32: 82089 | E32: 79746 | I32: =I10+I7-I27-I29 -> 4647.28 | J32: =J10+J7-J27-J29 -> -2286.2 | K32: =K10+K7-K27-K29 -> 11285.09 | L32: =L10+L7-L27-L29 -> 2678.7
A33: LIABILITIES
A34: Debt in Current Liabilities | B34: 6110 | C34: 6833 | D34: 7235 | E34: 5440
A35: Notes Payable | B35: 0 | C35: 0 | D35: 0 | E35: 0
A36: Debt - Due in One Year | B36: 6110 | C36: 6833 | D36: 7235 | E36: 5440 | H36: NOTE TO SELF *** Operating income before depreciation can be used as EBITDA) revenues - COGS and SG&A***
A37: Accounts Payable | B37: 27143 | C37: 18598 | D37: 19389 | E37: 20832 | H37: =I4-I5-I6 -> 8479
A38: Income Taxes Payable | B38: . | C38: . | D38: . | E38: .
A39: Current Liabilities - Other | B39: 22966 | C39: 26223 | D39: 21870 | E39: 20255 | H39: FCF is: Free Cash Flow = Unlevered net income + Depreciation - CapEx - Changes in NWC
A40: Accrued Expense | B40: . | C40: . | D40: . | E40: .
...

Sheet Template - Dell
A1: NPV for Dell's New Tablet Computer
A3: Assumptions (Amounts in Millions Unless Otherwise Indicated)
A4: Initial Capital Expenditure (Year 0) | B4: ='Dell''s Financial Statements'!E24*0.06 -> 885.36 | C4: <-- 6% of Gross PPE at the end of last fiscal year = 6%*"P.P.& E.- Total (Gross)"
A5: Useful Life of Assets (in year) | B5: 5 | C5: <-- 5-year
A6: Annual Depreciation | B6: =B4/B5 -> 177.072 | C6: <-- Annual depreciation = (Purchase value -Salvage value)/useful life, where purchase value equals the initial capital expenditure, and salvage value = 0
A7: EBITDA/Sales profit margin | B7: ='Dell''s Financial Statements'!L14 -> 0.10519322 | C7: <-- The EBITDA/Sales profit margin in the last year = Operating Income Before Depreciation/Sales (Net)
A8: Net working capital in the last year | B8: ='Dell''s Financial Statements'!L28 -> 1486 | C8: <-- accounts receivable + inventory - accounts payable = "Receivables" + "Inventories - Total" - "Accounts Payable"
A9: Net working capital/Sales (Net) in the last year | B9: ='Dell''s Financial Statements'!L28/'Dell''s Financial Statements'!L4 -> 0.0155493 | C9: <-- Net working capital/Sales (Net)
A10: Initial Net Working Capital (Year 0) | B10: =0.01*C19 -> 57.3402 | C10: <-- 1% of project sales in Year 1
A11: Net Working Capital in Year 5 | B11: 0 | C11: <-- At the end of the project life (Year 5), you recover all the net working capital for the project. (E.g., sell all inventory, collect receivable, and pay the accounts payable.) Thus, The NWC level in Year 5 equals zero.
A12: Tax Rate | B12: 0.21
A13: Cost of Capital | B13: 0.12
A14: Revenues in Year 1 | B14: =0.06*'Dell''s Financial Statements'!L4 -> 5734.02 | C14: <-- 6% of the company's total revenue in the last fiscal year = 6%* Sales (Net)
A15: Revenue Growth Rate per Year | D15: 0.1 | E15: 0.08 | F15: 0.03 | G15: 0.03
B16: Year | C16: Year | D16: Year | E16: Year | F16: Year | G16: Year
B17: 2025 | C17: =B17+1 -> 2026 | D17: =C17+1 -> 2027 | E17: =D17+1 -> 2028 | F17: =E17+1 -> 2029 | G17: =F17+1 -> 2030
A18: Unlevered Income Statements | B18: 0 | C18: 1 | D18: 2 | E18: 3 | F18: 4 | G18: 5
A19: Revenues | C19: =B14 -> 5734.02 | D19: =C19*(1+D15) -> 6307.422 | E19: =D19*(1+E15) -> 6812.0158 | F19: =E19*(1+F15) -> 7016.3762 | G19: =F19*(1+G15) -> 7226.8675
A20: EBITDA | C20: =$B$7*C19 -> 603.18 | D20: =$B$7*D19 -> 663.498 | E20: =$B$7*E19 -> 716.57784 | F20: =$B$7*F19 -> 738.07518 | G20: =$B$7*G19 -> 760.21743
A21: Depreciation | C21: =$B$6 -> 177.072 | D21: =$B$6 -> 177.072 | E21: =$B$6 -> 177.072 | F21: =$B$6 -> 177.072 | G21: =$B$6 -> 177.072
A22: Tax | C22: =(C20-C21)*$B$12 -> 89.48268 | D22: =(D20-D21)*$B$12 -> 102.14946 | E22: =(E20-E21)*$B$12 -> 113.29623 | F22: =(F20-F21)*$B$12 -> 117.81067 | G22: =(G20-G21)*$B$12 -> 122.46054
A23: Unlevered Net Income | C23: =(C20-C21)*(1-$B$12) -> 336.62532 | D23: =(D20-D21)*(1-$B$12) -> 384.27654 | E23: =(E20-E21)*(1-$B$12) -> 426.20961 | F23: =(F20-F21)*(1-$B$12) -> 443.19251 | G23: =(G20-G21)*(1-$B$12) -> 460.68489
A25: Working Capital Calculations
A26: NWC Level | B26: =B10 -> 57.3402 | C26: =('Dell''s Financial Statements'!$L$28/'Dell''s Financial Statements'!$L$4)*'Template - Dell'!C19 -> 89.16 | D26: =('Dell''s Financial Statements'!$L$28/'Dell''s Financial Statements'!$L$4)*'Template - Dell'!D19 -> 98.076 | E26: =('Dell''s Financial Statements'!$L$28/'Dell''s Financial Statements'!$L$4)*'Template - Dell'!E19 -> 105.92208 | F26: =('Dell''s Financial Statements'!$L$28/'Dell''s Financial Statements'!$L$4)*'Template - Dell'!F19 -> 109.09974 | G26: 0
A27: Change in NWC | C27: =C26-B26 -> 31.8198 | D27: =D26-C26 -> 8.916 | E27: =E26-D26 -> 7.84608 | F27: =F26-E26 -> 3.1776624 | G27: =G26-F26 -> -109.09974
A28: CF from Change in NWC | C28: =-C27 -> -31.8198 | D28: =-D27 -> -8.916 | E28: =-E27 -> -7.84608 | F28: =-F27 -> -3.1776624 | G28: =-G27 -> 109.09974
A30: Calculating Free Cash Flows
A31: Unlevered Net Income | C31: =C23 -> 336.62532 | D31: =D23 -> 384.27654 | E31: =E23 -> 426.20961 | F31: =F23 -> 443.19251 | G31: =G23 -> 460.68489
A32: Add Back Depreciation | C32: =C21 -> 177.072 | D32: =D21 -> 177.072 | E32: =E21 -> 177.072 | F32: =F21 -> 177.072 | G32: =G21 -> 177.072
A33: Subtract Change in NWC | C33: =C27 -> 31.8198 | D33: =D27 -> 8.916 | E33: =E27 -> 7.84608 | F33: =F27 -> 3.1776624 | G33: =G27 -> -109.09974
A34: Subtract Capital Expenditure | B34: =B4 -> 885.36 | C34: 0 | D34: 0 | E34: 0 | F34: 0 | G34: 0
A35: Free Cash Flow | B35: =-(B34+B26) -> -942.7002 | C35: =C31+C32-C34-C33 -> 481.87752 | D35: =D31+D32-D34-D33 -> 552.43254 | E35: =E31+E32-E34-E33 -> 595.43553 | F35: =F31+F32-F34-F33 -> 617.08685 | G35: =G31+G32-G34-G33 -> 746.85663
A37: Discount Factor (1/(1+r)^n) | B37: =(1/(1+$B$13)^B18) -> 1 | C37: =(1/(1+$B$13)^C18) -> 0.89285714 | D37: =(1/(1+$B$13)^D18) -> 0.79719388 | E37: =(1/(1+$B$13)^E18) -> 0.71178025 | F37: =(1/(1+$B$13)^F18) -> 0.63551808 | G37: =(1/(1+$B$13)^G18) -> 0.56742686
A38: PV(FCF) | B38: =B37*B35 -> -942.7002 | C38: =C37*C35 -> 430.24779 | D38: =D37*D35 -> 440.39584 | E38: =E37*E35 -> 423.81925 | F38: =F37*F35 -> 392.16985 | G38: =G37*G35 -> 423.78651
A39: NPV | B39: =B35+NPV(B13,C35,D35,E35,F35,G35) -> 1167.719

Sheet Sensitivity Analysis
A1: NPV for Dell's New Tablet Computer | I1: Copy your baseline projections to this sheet and do the sensitivity analysis in this sheet, so that your sensitivity analysis won't alter your baseline sheet.
A3: Assumptions (Amounts in Millions Unless Otherwise Indicated)
A4: Initial Capital Expenditure (Year 0) | B4: ='Dell''s Financial Statements'!E24*0.06 -> 885.36
A5: Useful Life of Assets (in year) | B5: 5
A6: Annual Depreciation | B6: =B4/B5 -> 177.072
A7: EBITDA/Sales profit margin | B7: ='Dell''s Financial Statements'!L14 -> 0.10519322
A8: Net working capital in the last year | B8: ='Dell''s Financial Statements'!L28 -> 1486
A9: Net working capital/Sales (Net) in the last year | B9: ='Dell''s Financial Statements'!L28/'Dell''s Financial Statements'!L4 -> 0.0155493 | I9: Sensitivity Analysis
A10: Initial Net Working Capital (Year 0) | B10: =0.01*C21 -> 57.3402 | I10: Parameter | J10: Initial Assumption | K10: Worst Case | L10: Best Case
A11: Net Working Capital in Year 5 | B11: 0 | I11: Sales in Year 1 | J11: 6% of Company's Revenues in the last fiscal year | K11: 2% of Company's Revenues in the last fiscal year | L11: 7% of Company's Revenues in the last fiscal year
A12: Tax Rate | B12: 0.21 | I12: NPV | J12: =B41 -> 1167.719 | K12: -133.25 | L12: 1492.96
A13: Cost of Capital | B13: 0.12
A14: Revenues in Year 1 (6%) | B14: =0.06*'Dell''s Financial Statements'!L4 -> 5734.02
A15: Revenues in Year 1 (2%) | B15: =0.02*'Dell''s Financial Statements'!L4 -> 1911.34
A16: Revenues in Year 1 (7%) | B16: =0.07*'Dell''s Financial Statements'!L4 -> 6689.69
A17: Revenue Growth Rate per Year | C17: 0.06 | D17: 0.1 | E17: 0.08 | F17: 0.03 | G17: 0.03
B18: Year | C18: Year | D18: Year | E18: Year | F18: Year | G18: Year
B19: 2025 | C19: =B19+1 -> 2026 | D19: =C19+1 -> 2027 | E19: =D19+1 -> 2028 | F19: =E19+1 -> 2029 | G19: =F19+1 -> 2030
A20: Unlevered Income Statements | B20: 0 | C20: 1 | D20: 2 | E20: 3 | F20: 4 | G20: 5
A21: Revenues | C21: =B14 -> 5734.02 | D21: =C21*(1+D17) -> 6307.422 | E21: =D21*(1+E17) -> 6812.0158 | F21: =E21*(1+F17) -> 7016.3762 | G21: =F21*(1+G17) -> 7226.8675
A22: EBITDA | C22: =$B$7*C21 -> 603.18 | D22: =$B$7*D21 -> 663.498 | E22: =$B$7*E21 -> 716.57784 | F22: =$B$7*F21 -> 738.07518 | G22: =$B$7*G21 -> 760.21743
A23: Depreciation | C23: =$B$6 -> 177.072 | D23: =$B$6 -> 177.072 | E23: =$B$6 -> 177.072 | F23: =$B$6 -> 177.072 | G23: =$B$6 -> 177.072
A24: Tax | C24: =(C22-C23)*$B$12 -> 89.48268 | D24: =(D22-D23)*$B$12 -> 102.14946 | E24: =(E22-E23)*$B$12 -> 113.29623 | F24: =(F22-F23)*$B$12 -> 117.81067 | G24: =(G22-G23)*$B$12 -> 122.46054
A25: Unlevered Net Income | C25: =(C22-C23)*(1-$B$12) -> 336.62532 | D25: =(D22-D23)*(1-$B$12) -> 384.27654 | E25: =(E22-E23)*(1-$B$12) -> 426.20961 | F25: =(F22-F23)*(1-$B$12) -> 443.19251 | G25: =(G22-G23)*(1-$B$12) -> 460.68489
A27: Working Capital Calculations
A28: NWC Level | B28: =B10 -> 57.3402 | C28: =('Dell''s Financial Statements'!$L$28/'Dell''s Financial Statements'!$L$4)*'Template - Dell'!C19 -> 89.16 | D28: =('Dell''s Financial Statements'!$L$28/'Dell''s Financial Statements'!$L$4)*'Template - Dell'!D19 -> 98.076 | E28: =('Dell''s Financial Statements'!$L$28/'Dell''s Financial Statements'!$L$4)*'Template - Dell'!E19 -> 105.92208 | F28: =('Dell''s Financial Statements'!$L$28/'Dell''s Financial Statements'!$L$4)*'Template - Dell'!F19 -> 109.09974 | G28: 0
A29: Change in NWC | C29: =C28-B28 -> 31.8198 | D29: =D28-C28 -> 8.916 | E29: =E28-D28 -> 7.84608 | F29: =F28-E28 -> 3.1776624 | G29: =G28-F28 -> -109.09974
A30: CF from Change in NWC | C30: =-C29 -> -31.8198 | D30: =-D29 -> -8.916 | E30: =-E29 -> -7.84608 | F30: =-F29 -> -3.1776624 | G30: =-G29 -> 109.09974
A32: Calculating Free Cash Flows
A33: Unlevered Net Income | C33: =C25 -> 336.62532 | D33: =D25 -> 384.27654 | E33: =E25 -> 426.20961 | F33: =F25 -> 443.19251 | G33: =G25 -> 460.68489
A34: Add Back Depreciation | C34: =C23 -> 177.072 | D34: =D23 -> 177.072 | E34: =E23 -> 177.072 | F34: =F23 -> 177.072 | G34: =G23 -> 177.072
A35: Subtract Change in NWC | C35: =C29 -> 31.8198 | D35: =D29 -> 8.916 | E35: =E29 -> 7.84608 | F35: =F29 -> 3.1776624 | G35: =G29 -> -109.09974
A36: Subtract Capital Expenditure | B36: =B4 -> 885.36 | C36: 0 | D36: 0 | E36: 0 | F36: 0 | G36: 0
A37: Free Cash Flow | B37: =-(B36+B28) -> -942.7002 | C37: =C33+C34-C36-C35 -> 481.87752 | D37: =D33+D34-D36-D35 -> 552.43254 | E37: =E33+E34-E36-E35 -> 595.43553 | F37: =F33+F34-F36-F35 -> 617.08685 | G37: =G33+G34-G36-G35 -> 746.85663
A39: Discount Factor (1/(1+r)^n)
A40: PV(FCF)
A41: NPV | B41: =B37+NPV(B13,C37,D37,E37,F37,G37) -> 1167.719

Sheet SMA
A1: Financial Statement for: MICROSOFT CORP
A2: Fiscal Years: 2018 to 2024 | K2: CapEx | S2: Year | T2: CapEx | U2: 3MA
B3: 2018 | C3: 2019 | D3: 2020 | E3: 2021 | F3: 2022 | G3: 2023 | H3: 2024 | K3: 2018 | L3: 2019 | M3: 2020 | N3: 2021 | O3: 2022 | P3: 2023 | Q3: 2024 | S3: 2018 | T3: =K4 -> 11632000000
K4: 11632000000 | L4: 13925000000 | M4: 15441000000 | N4: 20622000000 | O4: 23886000000 | P4: 28107000000 | Q4: 44477000000 | S4: 2019 | T4: =L4 -> 13925000000
A5: BALANCE SHEET | S5: 2020 | T5: =M4 -> 15441000000 | U5: =(T5+T4+T3)/3 -> 13666000000
A6: ASSETS | S6: 2021 | T6: =N4 -> 20622000000 | U6: =(T6+T5+T4)/3 -> 1.6662667e+10
A7: Cash and Short-Term Investments | B7: 133768 | C7: 133819 | D7: 136527 | E7: 130334 | F7: 104757 | G7: 111262 | H7: 75543 | S7: 2022 | T7: =O4 -> 23886000000 | U7: =(T7+T6+T5)/3 -> 19983000000
A8: Cash | B8: 11946 | C8: 11356 | D8: 13576 | E8: 14224 | F8: 13931 | G8: 34704 | H8: 18315 | S8: 2023 | T8: =P4 -> 28107000000 | U8: =(T8+T7+T6)/3 -> 24205000000
A9: Short-Term Investments | B9: 121822 | C9: 122463 | D9: 122951 | E9: 116110 | F9: 90826 | G9: 76558 | H9: 57228 | S9: 2024 | T9: =Q4 -> 44477000000 | U9: =(T9+T8+T7)/3 -> 3.2156667e+10
A10: Receivables | B10: 26481 | C10: 29524 | D10: 32011 | E10: 38043 | F10: 50361 | G10: 57888 | H10: 67424
A11: Receivables - Trade | B11: 26481 | C11: 29524 | D11: 32011 | E11: 38043 | F11: 44261 | G11: 48688 | H11: 56924
A12: Income Tax Refund | B12: 0 | C12: 0 | D12: 0 | E12: 0 | F12: 0 | G12: 0 | H12: 0
A13: Current Receivables - Other | B13: 0 | C13: 0 | D13: 0 | E13: 0 | F13: 6100 | G13: 9200 | H13: 10500
A14: Inventories - Total | B14: 2662 | C14: 2063 | D14: 1895 | E14: 2636 | F14: 3742 | G14: 2500 | H14: 1246
A15: Inventories - Raw Materials | B15: 655 | C15: 399 | D15: 700 | E15: 1190 | F15: 1144 | G15: 709 | H15: 394
A16: Inventories - Work in Process | B16: 54 | C16: 53 | D16: 83 | E16: 79 | F16: 82 | G16: 23 | H16: 7
A17: Inventories - Finished Goods | B17: 1953 | C17: 1611 | D17: 1112 | E17: 1367 | F17: 2516 | G17: 1768 | H17: 845 | S17: Year | T17: CapEx | U17: 3MA
A18: Inventories - Other | B18: 0 | C18: 0 | D18: 0 | E18: 0 | F18: 0 | G18: 0 | H18: 0 | S18: 2020 | T18: =T5 -> 15441000000 | U18: =U5 -> 13666000000
A19: Current Assets - Other | B19: 6751 | C19: 10146 | D19: 11482 | E19: 13393 | F19: 10824 | G19: 12607 | H19: 15521 | S19: 2021 | T19: =T6 -> 20622000000 | U19: =U6 -> 1.6662667e+10
A20: Prepaid Expense | B20: 0 | C20: 0 | D20: 0 | E20: 0 | F20: 0 | G20: 0 | H20: 0 | S20: 2022 | T20: =T7 -> 23886000000 | U20: =U7 -> 19983000000
A21: Other Curr.Asst, Excl.Ppd.Exp. | B21: 6751 | C21: 10146 | D21: 11482 | E21: 13393 | F21: 10824 | G21: 12607 | H21: 15521 | S21: 2023 | T21: =T8 -> 28107000000 | U21: =U8 -> 24205000000
A22: Current Assets - Total | B22: 169662 | C22: 175552 | D22: 181915 | E22: 184406 | F22: 169684 | G22: 184257 | H22: 159734 | S22: 2024 | T22: =T9 -> 44477000000 | U22: =U9 -> 3.2156667e+10
A23: Prop.Plant & Equip.- Total (Net) | B23: 36146 | C23: 43856 | D23: 52904 | E23: 70803 | F23: 87546 | G23: 109987 | H23: 154552
A24: P.P.& E.- Total (Gross) | B24: 65369 | C24: 79186 | D24: 96101 | E24: 122154 | F24: 147206 | G24: 178238 | H24: 230973
A25: Deprec.Depl.& Amort. | B25: 29223 | C25: 35330 | D25: 43197 | E25: 51351 | F25: 59660 | G25: 68251 | H25: 76421
A26: Invest. & Advances - Eq.Meth. | B26: . | C26: . | D26: . | E26: . | F26: . | G26: . | H26: 6000
A27: Invest. & Advances - Other | B27: 3662 | C27: 4849 | D27: 5665 | E27: 9384 | F27: 10691 | G27: 14379 | H27: 13500
A28: Intangibles | B28: 43736 | C28: 49776 | D28: 50389 | E28: 57511 | F28: 78822 | G28: 77252 | H28: 146817
A29: Assets - Other | B29: 5642 | C29: 12523 | D29: 10438 | E29: 11675 | F29: 18097 | G29: 26101 | H29: 31560
A30: Deferred Charges | B30: 0 | C30: 0 | D30: 0 | E30: 0 | F30: 0 | G30: 0 | H30: 0
A31: Other Asst., Excl.Def.Chg. | B31: 5642 | C31: 12523 | D31: 10438 | E31: 11675 | F31: 18097 | G31: 26101 | H31: 31560
A32: Assets - Total | B32: 258848 | C32: 286556 | D32: 301311 | E32: 333779 | F32: 364840 | G32: 411976 | H32: 512163
A33: LIABILITIES
A34: Debt in Current Liabilities | B34: 5573 | C34: 7348 | D34: 5905 | E34: 10825 | F34: 6037 | G34: 8853 | H34: 14871
A35: Notes Payable | B35: 0 | C35: 0 | D35: 0 | E35: 0 | F35: 0 | G35: 0 | H35: 6693
A36: Debt - Due in One Year | B36: 5573 | C36: 7348 | D36: 5905 | E36: 10825 | F36: 6037 | G36: 8853 | H36: 8178
A37: Accounts Payable | B37: 8617 | C37: 9382 | D37: 12530 | E37: 15163 | F37: 19000 | G37: 18095 | H37: 21996 | K37: Revenue | S37: Year | T37: Revenue | U37: 3MA
A38: Income Taxes Payable | B38: 2121 | C38: 5665 | D38: 2130 | E38: 2174 | F38: 4067 | G38: 4152 | H38: 5017 | K38: 2018 | L38: 2019 | M38: 2020 | N38: 2021 | O38: 2022 | P38: 2023 | Q38: 2024 | S38: 2018 | T38: =K39 -> 110360000000
A39: Current Liabilities - Other | B39: 42177 | C39: 47025 | D39: 51745 | E39: 60495 | F39: 65978 | G39: 73049 | H39: 83402 | K39: 110360000000 | L39: 125843000000 | M39: 143015000000 | N39: 168088000000 | O39: 198270000000 | P39: 211915000000 | Q39: 245122000000 | S39: 2019 | T39: =L39 -> 125843000000
A40: Accrued Expense | B40: 6103 | C40: 6830 | D40: 7874 | E40: 10057 | F40: 10661 | G40: 11009 | H40: 12564 | S40: 2020 | T40: =M39 -> 143015000000 | U40: =(T40+T39+T38)/3 -> 126406000000
...

Sheet Your Company's FS
A1: Financial Statement for: MICROSOFT CORP | I1: Download your company's financial statements in the last four fiscal years from WRDS and copy them to this sheet.
A2: Fiscal Years: 2021 to 2024
B3: 2021 | C3: 2022 | D3: 2023 | E3: 2024
A5: BALANCE SHEET
A6: ASSETS
A7: Cash and Short-Term Investments | B7: 130334 | C7: 104757 | D7: 111262 | E7: 75543
A8: Cash | B8: 14224 | C8: 13931 | D8: 34704 | E8: 18315 | I8: Unlevered net income = (Revenues - Costs - Depreciation) * (1 – tax rate)
A9: Short-Term Investments | B9: 116110 | C9: 90826 | D9: 76558 | E9: 57228
A10: Receivables | B10: 38043 | C10: 50361 | D10: 57888 | E10: 67424 | I10: 2021 | J10: =I10+1 -> 2022 | K10: =J10+1 -> 2023 | L10: =K10+1 -> 2024
A11: Receivables - Trade | B11: 38043 | C11: 44261 | D11: 48688 | E11: 56924 | H11: Revenues | I11: 168088 | J11: 198270 | K11: 211915 | L11: 245122
A12: Income Tax Refund | B12: 0 | C12: 0 | D12: 0 | E12: 0 | H12: COGS | I12: 41332 | J12: 48050 | K12: 52211 | L12: 54114
A13: Current Receivables - Other | B13: 0 | C13: 6100 | D13: 9200 | E13: 10500 | H13: SG&A | I13: 45940 | J13: 52111 | K13: 56510 | L13: 61575
A14: Inventories - Total | B14: 2636 | C14: 3742 | D14: 2500 | E14: 1246 | H14: Depreciation & Amortization | I14: 10900 | J14: 14600 | K14: 13500 | L14: 20000
A15: Inventories - Raw Materials | B15: 1190 | C15: 1144 | D15: 709 | E15: 394 | H15: Tax Rate | I15: 0.21 | J15: 0.21 | K15: 0.21 | L15: 0.21
A16: Inventories - Work in Process | B16: 79 | C16: 82 | D16: 23 | E16: 7
A17: Inventories - Finished Goods | B17: 1367 | C17: 2516 | D17: 1768 | E17: 845 | H17: Unlevered Net Income | I17: =(I11-I12-I13-I14)*(1-I15) -> 55233.64 | J17: =(J11-J12-J13-J14)*(1-J15) -> 65972.11 | K17: =(K11-K12-K13-K14)*(1-K15) -> 70858.26 | L17: =(L11-L12-L13-L14)*(1-L15) -> 86452.07
A18: Inventories - Other | B18: 0 | C18: 0 | D18: 0 | E18: 0
A19: Current Assets - Other | B19: 13393 | C19: 10824 | D19: 12607 | E19: 15521 | H19: Operating Income Before Depreciation = EBITDA | I19: 80816 | J19: 98109 | K19: 103194 | L19: 129433
A20: Prepaid Expense | B20: 0 | C20: 0 | D20: 0 | E20: 0 | O20: .
A21: Other Curr.Asst, Excl.Ppd.Exp. | B21: 13393 | C21: 10824 | D21: 12607 | E21: 15521 | H21: EBITDA/Sales Profit Margin | I21: =I19/I11 -> 0.48079577 | J21: =J19/J11 -> 0.49482524 | K21: =K19/K11 -> 0.48695939 | L21: =L19/L11 -> 0.52803502
A22: Current Assets - Total | B22: 184406 | C22: 169684 | D22: 184257 | E22: 159734
A23: Prop.Plant & Equip.- Total (Net) | B23: 70803 | C23: 87546 | D23: 109987 | E23: 154552
A24: P.P.& E.- Total (Gross) | B24: 122154 | C24: 147206 | D24: 178238 | E24: 230973 | I24: Operating Cash Flow
A25: Deprec.Depl.& Amort. | B25: 51351 | C25: 59660 | D25: 68251 | E25: 76421
A26: Invest. & Advances - Eq.Meth. | B26: . | C26: . | D26: . | E26: 6000 | H26: ( - ) Accounts Receivables | I26: 38043 | J26: 50361 | K26: 57888 | L26: 67424
A27: Invest. & Advances - Other | B27: 9384 | C27: 10691 | D27: 14379 | E27: 13500 | H27: ∆ Accounts Receivables | J27: =J26-I26 -> 12318 | K27: =K26-J26 -> 7527 | L27: =L26-K26 -> 9536
A28: Intangibles | B28: 57511 | C28: 78822 | D28: 77252 | E28: 146817 | H28: ( - ) Inventory | I28: 2636 | J28: 3742 | K28: 2500 | L28: 1246
A29: Assets - Other | B29: 11675 | C29: 18097 | D29: 26101 | E29: 31560 | H29: ∆ Inventory | J29: =J28-I28 -> 1106 | K29: =K28-J28 -> -1242 | L29: =L28-K28 -> -1254
A30: Deferred Charges | B30: 0 | C30: 0 | D30: 0 | E30: 0 | H30: ( + ) Accounts Payable | I30: 15163 | J30: 19000 | K30: 18095 | L30: 21996
A31: Other Asst., Excl.Def.Chg. | B31: 11675 | C31: 18097 | D31: 26101 | E31: 31560 | H31: ∆ Accounts Payable | J31: =J30-I30 -> 3837 | K31: =K30-J30 -> -905 | L31: =L30-K30 -> 3901
A32: Assets - Total | B32: 333779 | C32: 364840 | D32: 411976 | E32: 512163 | H32: ( + ) Net Income
A33: LIABILITIES | H33: ( + ) Depreciation | I33: =I14 -> 10900 | J33: =J14 -> 14600 | K33: =K14 -> 13500 | L33: =L14 -> 20000
A34: Debt in Current Liabilities | B34: 10825 | C34: 6037 | D34: 8853 | E34: 14871 | H34: ( - ) Capital Expenditures | I34: 20622 | J34: 23886 | K34: 28107 | L34: 44477
A35: Notes Payable | B35: 0 | C35: 0 | D35: 0 | E35: 6693 | H35: NWC | I35: =I26+I28-I30 -> 25516 | J35: =J26+J28-J30 -> 35103 | K35: =K26+K28-K30 -> 42293 | L35: =L26+L28-L30 -> 46674
A36: Debt - Due in One Year | B36: 10825 | C36: 6037 | D36: 8853 | E36: 8178 | H36: ∆NWC | J36: =J35-I35 -> 9587 | K36: =K35-J35 -> 7190 | L36: =L35-K35 -> 4381
A37: Accounts Payable | B37: 15163 | C37: 19000 | D37: 18095 | E37: 21996
A38: Income Taxes Payable | B38: 2174 | C38: 4067 | D38: 4152 | E38: 5017 | I38: Free Cash Flow
A39: Current Liabilities - Other | B39: 60495 | C39: 65978 | D39: 73049 | E39: 83402 | I39: =I17+I14-I34-I36 -> 45511.64 | J39: =J17+J14-J34-J36 -> 47099.11 | K39: =K17+K14-K34-K36 -> 49061.26 | L39: =L17+L14-L34-L36 -> 57594.07
A40: Accrued Expense | B40: 10057 | C40: 10661 | D40: 11009 | E40: 12564
A41: Other Curr.Liab., Excl.Accr.Exp. | B41: 50438 | C41: 55317 | D41: 62040 | E41: 70838
...

Sheet DCF Analysis for Your Project
A1: NPV for Your Company's Project | E1: Implement the DCF analysis for YOUR project in this sheet, not Dell's.
A3: Assumptions (Amounts in Millions Unless Otherwise Indicated)
A4: Initial Capital Expenditure (Year 0) | B4: 14000 | C4: Based on research that was conducted and real-world analogs, a total project cost of $14 billion
A5: Useful Life of Assets (in year) | B5: 5 | C5: <-- 5-year
A6: Annual Depreciation | B6: =B4/B5 -> 2800 | C6: <-- Annual depreciation = (Purchase value -Salvage value)/useful life, where purchase value equals the initial capital expenditure, and salvage value = 0
A7: EBITDA/Sales profit margin | B7: ='Your Company''s FS'!L21 -> 0.52803502 | C7: <-- The EBITDA/Sales profit margin in the last year = Operating Income Before Depreciation/Sales (Net)
A8: Net working capital in the last year | B8: ='Your Company''s FS'!L35 -> 46674 | C8: <-- accounts receivable + inventory - accounts payable = "Receivables" + "Inventories - Total" - "Accounts Payable"
A9: Net working capital/Sales (Net) in the last year | B9: ='Your Company''s FS'!L35/'Your Company''s FS'!L11 -> 0.19041131 | C9: <-- Net working capital/Sales (Net)
A10: Initial Net Working Capital (Year 0) | B10: =0.01*C19 -> 147.0732 | C10: <-- 1% of project sales in Year 1
A11: Net Working Capital in Year 5 | B11: 0 | C11: <-- At the end of the project life (Year 5), you recover all the net working capital for the project. (E.g., sell all inventory, collect receivable, and pay the accounts payable.) Thus, The NWC level in Year 5 equals zero.
A12: Tax Rate | B12: 0.21 | C12: 0.28
A13: Cost of Capital | B13: 0.12
A14: Revenues in Year 1 | B14: =0.06*'Your Company''s FS'!L11 -> 14707.32 | C14: <-- 6% of the company's total revenue in the last fiscal year = 6%* Sales (Net)
A15: Revenue Growth Rate per Year | C15: 0.06 | D15: 0.15 | E15: 0.14 | F15: 0.1 | G15: 0.06
B16: Year | C16: Year | D16: Year | E16: Year | F16: Year | G16: Year
B17: ='Template - Dell'!B17 -> 2025 | C17: =B17+1 -> 2026 | D17: =C17+1 -> 2027 | E17: =D17+1 -> 2028 | F17: =E17+1 -> 2029 | G17: =F17+1 -> 2030
A18: Unlevered Income Statements | B18: 0 | C18: 1 | D18: 2 | E18: 3 | F18: 4 | G18: 5
A19: Revenues | C19: =B14 -> 14707.32 | D19: =C19*(1+D15) -> 16913.418 | E19: =D19*(1+E15) -> 19281.297 | F19: =E19*(1+F15) -> 21209.426 | G19: =F19*(1+G15) -> 22481.992
A20: EBITDA | C20: =C19*$B$7 -> 7765.98 | D20: =D19*$B$7 -> 8930.877 | E20: =E19*$B$7 -> 10181.2 | F20: =F19*$B$7 -> 11199.32 | G20: =G19*$B$7 -> 11871.279
A21: Depreciation | C21: =B6 -> 2800 | D21: =C21 -> 2800 | E21: =D21 -> 2800 | F21: =E21 -> 2800 | G21: =F21 -> 2800
A22: Tax | C22: =(C20-C21)*$B$12 -> 1042.8558 | D22: =(D20-D21)*$B$12 -> 1287.4842 | E22: =(E20-E21)*$B$12 -> 1550.052 | F22: =(F20-F21)*$B$12 -> 1763.8571 | G22: =(G20-G21)*$B$12 -> 1904.9686
A23: Unlevered Net Income | C23: =(C20-C21)*(1-$B$12) -> 3923.1242 | D23: =(D20-D21)*(1-$B$12) -> 4843.3928 | E23: =(E20-E21)*(1-$B$12) -> 5831.1478 | F23: =(F20-F21)*(1-$B$12) -> 6635.4626 | G23: =(G20-G21)*(1-$B$12) -> 7166.3104
A25: Working Capital Calculations
A26: NWC Level | B26: =B10 -> 147.0732 | C26: =C19*$B$9 -> 2800.44 | D26: =D19*$B$9 -> 3220.506 | E26: =E19*$B$9 -> 3671.3768 | F26: =F19*$B$9 -> 4038.5145 | G26: 0
A27: Change in NWC | C27: =C26-B26 -> 2653.3668 | D27: =D26-C26 -> 420.066 | E27: =E26-D26 -> 450.87084 | F27: =F26-E26 -> 367.13768 | G27: =G26-F26 -> -4038.5145
A28: CF from Change in NWC | C28: =-C27 -> -2653.3668 | D28: =-D27 -> -420.066 | E28: =-E27 -> -450.87084 | F28: =-F27 -> -367.13768 | G28: =-G27 -> 4038.5145
A30: Calculating Free Cash Flows
A31: Unlevered Net Income | C31: =(C20-C21)*(1-$B$12) -> 3923.1242 | D31: =(D20-D21)*(1-$B$12) -> 4843.3928 | E31: =(E20-E21)*(1-$B$12) -> 5831.1478 | F31: =(F20-F21)*(1-$B$12) -> 6635.4626 | G31: =(G20-G21)*(1-$B$12) -> 7166.3104
A32: Add Back Depreciation | C32: =C21 -> 2800 | D32: =D21 -> 2800 | E32: =E21 -> 2800 | F32: =F21 -> 2800 | G32: =G21 -> 2800
A33: Subtract Change in NWC | C33: =C27 -> 2653.3668 | D33: =D27 -> 420.066 | E33: =E27 -> 450.87084 | F33: =F27 -> 367.13768 | G33: =G27 -> -4038.5145
A34: Subtract Capital Expenditure | B34: =B4 -> 14000 | C34: 0 | D34: 0 | E34: 0 | F34: 0 | G34: 0
A35: Free Cash Flow | B35: =-(B34+B26) -> -14147.073 | C35: =C31+C32-C33-C34 -> 4069.7574 | D35: =D31+D32-D33-D34 -> 7223.3268 | E35: =E31+E32-E33-E34 -> 8180.277 | F35: =F31+F32-F33-F34 -> 9068.3249 | G35: =G31+G32-G33-G34 -> 14004.825
A37: Discount Factor (1/(1+r)^n) | B37: =(1/(1+$B$13)^B18) -> 1 | C37: =(1/(1+$B$13)^C18) -> 0.89285714 | D37: =(1/(1+$B$13)^D18) -> 0.79719388 | E37: =(1/(1+$B$13)^E18) -> 0.71178025 | F37: =(1/(1+$B$13)^F18) -> 0.63551808 | G37: =(1/(1+$B$13)^G18) -> 0.56742686
A38: PV(FCF) | B38: =B35*B37 -> -14147.073 | C38: =C35*C37 -> 3633.712 | D38: =D35*D37 -> 5758.3919 | E38: =E35*E37 -> 5822.5596 | F38: =F35*F37 -> 5763.0844 | G38: =G35*G37 -> 7946.7138
A39: NPV | B39: =B35+NPV(B13,C35,D35,E35,F35,G35) -> 14777.388

Sheet Alternative Profitability
A1: NPV for Your Company's Project | E1: Alternative Profitability based off industry standard
A3: Assumptions (Amounts in Millions Unless Otherwise Indicated)
A4: Initial Capital Expenditure (Year 0) | B4: 14000 | C4: Based on research that was conducted and real-world analogs, a total project cost of $14 billion
A5: Useful Life of Assets (in year) | B5: 5 | C5: <-- 5-year
A6: Annual Depreciation | B6: =B4/B5 -> 2800 | C6: <-- Annual depreciation = (Purchase value -Salvage value)/useful life, where purchase value equals the initial capital expenditure, and salvage value = 0
A7: EBITDA/Sales profit margin | B7: 0.28 | C7: <-- The EBITDA/Sales profit margin in the last year = Operating Income Before Depreciation/Sales (Net)
A8: Net working capital in the last year | B8: ='Your Company''s FS'!L35 -> 46674 | C8: <-- accounts receivable + inventory - accounts payable = "Receivables" + "Inventories - Total" - "Accounts Payable"
A9: Net working capital/Sales (Net) in the last year | B9: ='Your Company''s FS'!L35/'Your Company''s FS'!L11 -> 0.19041131 | C9: <-- Net working capital/Sales (Net)
A10: Initial Net Working Capital (Year 0) | B10: =0.01*C19 -> 147.0732 | C10: <-- 1% of project sales in Year 1
A11: Net Working Capital in Year 5 | B11: 0 | C11: <-- At the end of the project life (Year 5), you recover all the net working capital for the project. (E.g., sell all inventory, collect receivable, and pay the accounts payable.) Thus, The NWC level in Year 5 equals zero.
A12: Tax Rate | B12: 0.21
A13: Cost of Capital | B13: 0.12
A14: Revenues in Year 1 | B14: =0.06*'Your Company''s FS'!L11 -> 14707.32 | C14: <-- 6% of the company's total revenue in the last fiscal year = 6%* Sales (Net)
A15: Revenue Growth Rate per Year | C15: 0.06 | D15: 0.15 | E15: 0.14 | F15: 0.1 | G15: 0.06
B16: Year | C16: Year | D16: Year | E16: Year | F16: Year | G16: Year
B17: ='Template - Dell'!B17 -> 2025 | C17: =B17+1 -> 2026 | D17: =C17+1 -> 2027 | E17: =D17+1 -> 2028 | F17: =E17+1 -> 2029 | G17: =F17+1 -> 2030
A18: Unlevered Income Statements | B18: 0 | C18: 1 | D18: 2 | E18: 3 | F18: 4 | G18: 5
A19: Revenues | C19: =B14 -> 14707.32 | D19: =C19*(1+D15) -> 16913.418 | E19: =D19*(1+E15) -> 19281.297 | F19: =E19*(1+F15) -> 21209.426 | G19: =F19*(1+G15) -> 22481.992
A20: EBITDA | C20: =C19*$B$7 -> 4118.0496 | D20: =D19*$B$7 -> 4735.757 | E20: =E19*$B$7 -> 5398.763 | F20: =F19*$B$7 -> 5938.6393 | G20: =G19*$B$7 -> 6294.9577
A21: Depreciation | C21: =B6 -> 2800 | D21: =C21 -> 2800 | E21: =D21 -> 2800 | F21: =E21 -> 2800 | G21: =F21 -> 2800
A22: Tax | C22: =(C20-C21)*$B$12 -> 276.79042 | D22: =(D20-D21)*$B$12 -> 406.50898 | E22: =(E20-E21)*$B$12 -> 545.74024 | F22: =(F20-F21)*$B$12 -> 659.11426 | G22: =(G20-G21)*$B$12 -> 733.94111
A23: Unlevered Net Income | C23: =(C20-C21)*(1-$B$12) -> 1041.2592 | D23: =(D20-D21)*(1-$B$12) -> 1529.2481 | E23: =(E20-E21)*(1-$B$12) -> 2053.0228 | F23: =(F20-F21)*(1-$B$12) -> 2479.5251 | G23: =(G20-G21)*(1-$B$12) -> 2761.0166
A25: Working Capital Calculations
A26: NWC Level | B26: =B10 -> 147.0732 | C26: =C19*$B$9 -> 2800.44 | D26: =D19*$B$9 -> 3220.506 | E26: =E19*$B$9 -> 3671.3768 | F26: =F19*$B$9 -> 4038.5145 | G26: 0
A27: Change in NWC | C27: =C26-B26 -> 2653.3668 | D27: =D26-C26 -> 420.066 | E27: =E26-D26 -> 450.87084 | F27: =F26-E26 -> 367.13768 | G27: =G26-F26 -> -4038.5145
A28: CF from Change in NWC | C28: =-C27 -> -2653.3668 | D28: =-D27 -> -420.066 | E28: =-E27 -> -450.87084 | F28: =-F27 -> -367.13768 | G28: =-G27 -> 4038.5145
A30: Calculating Free Cash Flows
A31: Unlevered Net Income | C31: =(C20-C21)*(1-$B$12) -> 1041.2592 | D31: =(D20-D21)*(1-$B$12) -> 1529.2481 | E31: =(E20-E21)*(1-$B$12) -> 2053.0228 | F31: =(F20-F21)*(1-$B$12) -> 2479.5251 | G31: =(G20-G21)*(1-$B$12) -> 2761.0166
A32: Add Back Depreciation | C32: =C21 -> 2800 | D32: =D21 -> 2800 | E32: =E21 -> 2800 | F32: =F21 -> 2800 | G32: =G21 -> 2800
A33: Subtract Change in NWC | C33: =C27 -> 2653.3668 | D33: =D27 -> 420.066 | E33: =E27 -> 450.87084 | F33: =F27 -> 367.13768 | G33: =G27 -> -4038.5145
A34: Subtract Capital Expenditure | B34: =B4 -> 14000 | C34: 0 | D34: 0 | E34: 0 | F34: 0 | G34: 0
A35: Free Cash Flow | B35: =-(B34+B26) -> -14147.073 | C35: =C31+C32-C33-C34 -> 1187.8924 | D35: =D31+D32-D33-D34 -> 3909.1821 | E35: =E31+E32-E33-E34 -> 4402.152 | F35: =F31+F32-F33-F34 -> 4912.3874 | G35: =G31+G32-G33-G34 -> 9599.5311
A37: Discount Factor (1/(1+r)^n) | B37: =(1/(1+$B$13)^B18) -> 1 | C37: =(1/(1+$B$13)^C18) -> 0.89285714 | D37: =(1/(1+$B$13)^D18) -> 0.79719388 | E37: =(1/(1+$B$13)^E18) -> 0.71178025 | F37: =(1/(1+$B$13)^F18) -> 0.63551808 | G37: =(1/(1+$B$13)^G18) -> 0.56742686
A38: PV(FCF) | B38: =B35*B37 -> -14147.073 | C38: =C35*C37 -> 1060.6182 | D38: =D35*D37 -> 3116.376 | E38: =E35*E37 -> 3133.3648 | F38: =F35*F37 -> 3121.911 | G38: =G35*G37 -> 5447.0317
A39: NPV | B39: =B35+NPV(B13,C35,D35,E35,F35,G35) -> 1732.2286
