Workbook

Sheet Dell's_Financial_Statements
A1: Financial Statement for: DELL TECHNOLOGIES INC | B1: 2021 | C1: 2022 | D1: 2023 | E1: 2024 | I1: 2021 | J1: 2022 | K1: 2023 | L1: 2024
A2: Fiscal Years: 2021 to 2024
H3: Income Statement
H4: Revenues | I4: =B74 -> 101197 | J4: =C74 -> 102301 | K4: =D74 -> 88425 | L4: =E74 -> 95567
H5: - COGS | I5: =B75 -> 76802 | J5: =C75 -> 76907 | K5: =D75 -> 64655 | L5: =E75 -> 71468
A6: BALANCE SHEET | H6: = Gross Profit | I6: =I4-I5 -> 24395 | J6: =J4-J5 -> 25394 | K6: =K4-K5 -> 23770 | L6: =L4-L5 -> 24099
A7: ASSETS | H7: - SG&A | I7: =B76 -> 15916 | J7: =C76 -> 15918 | K7: =D76 -> 14596 | L7: =E76 -> 14046
A8: Cash and Short-Term Investments | B8: 10011 | C8: 8879 | D8: 7502 | E8: 3756 | H8: = EBITDA / Operating Income before D&A | I8: =I6-I7 -> 8479 | J8: =J6-J7 -> 9476 | K8: =K6-K7 -> 9174 | L8: =L6-L7 -> 10053
A9: Cash | B9: 9477 | C9: 8607 | D9: 7366 | E9: 3633 | H9: - Depreciation & Amortization | I9: =B78 -> 3547 | J9: =C78 -> 3156 | K9: =D78 -> 3303 | L9: =E78 -> 3123
A10: Short-Term Investments | B10: 534 | C10: 272 | D10: 136 | E10: 123 | H10: = EBIT/ Operating Income After D&A | I10: =I8-I9 -> 4932 | J10: =J8-J9 -> 6320 | K10: =K8-K9 -> 5871 | L10: =L8-L9 -> 6930
A11: Receivables | B11: 18132 | C11: 18141 | D11: 13986 | E11: 15602 | H11: - EFF Tax Rate | I11: =I20/I19 -> 0.16562553 | J11: =J20/J19 -> 0.24899225 | K11: =K20/K19 -> 0.17802933 | L11: =L20/L19 -> 0.093502377
A12: Receivables - Trade | B12: 18001 | C12: 17763 | D12: 13986 | E12: 15602 | H12: = NOPAT | I12: =I10*(1-I11) -> 4115.1349 | J12: =J10*(1-J11) -> 4746.369 | K12: =K10*(1-K11) -> 4825.7898 | L12: =L10*(1-L11) -> 6282.0285
A13: Income Tax Refund | B13: 0 | C13: 0 | D13: 0 | E13: 0
A14: Current Receivables - Other | B14: 131 | C14: 378 | D14: 0 | E14: 0
A15: Inventories - Total | B15: 5898 | C15: 4776 | D15: 3622 | E15: 6716 | H15: EBIT/ Operating Income After D&A | I15: =I10 -> 4932 | J15: =J10 -> 6320 | K15: =K10 -> 5871 | L15: =L10 -> 6930
A16: Inventories - Raw Materials | B16: 3653 | C16: 3225 | D16: 2321 | E16: 4432 | H16: - Interest Expense | I16: =B83 -> 1542 | J16: =C83 -> 1222 | K16: =D83 -> 1501 | L16: =E83 -> 1394
A17: Inventories - Work in Process | B17: 855 | C17: 708 | D17: 607 | E17: 1128 | H17: +/- Nonoperating Income (Expense) | I17: =B84 -> 410 | J17: =C84 -> -259 | K17: =D84 -> 109 | L17: =E84 -> 205
A18: Inventories - Finished Goods | B18: 1390 | C18: 843 | D18: 694 | E18: 1156 | H18: +/- Special Items | I18: =B87 -> 2123 | J18: =C87 -> -1614 | K18: =D87 -> -592 | L18: =E87 -> -693
A19: Inventories - Other | B19: 0 | C19: 0 | D19: 0 | E19: 0 | H19: =Pretax Income | I19: =I15-I16+I17+I18 -> 5923 | J19: =J15-J16+J17+J18 -> 3225 | K19: =K15-K16+K17+K18 -> 3887 | L19: =L15-L16+L17+L18 -> 5048
A20: Current Assets - Other | B20: 10992 | C20: 10555 | D20: 10837 | E20: 10155 | H20: - Income Taxes | I20: =B91 -> 981 | J20: =C91 -> 803 | K20: =D91 -> 692 | L20: =E91 -> 472
A21: Prepaid Expense | B21: 886 | C21: 641 | D21: 589 | E21: 564 | H21: = Income Before Extradoniary Items | I21: =I19-I20 -> 4942 | J21: =J19-J20 -> 2422 | K21: =K19-K20 -> 3195 | L21: =L19-L20 -> 4576
A22: Other Curr.Asst, Excl.Ppd.Exp. | B22: 10106 | C22: 9914 | D22: 10248 | E22: 9591 | H22: -Minority Interest | I22: =B100 -> -6 | J22: =C100 -> -20 | K22: =D100 -> -16 | L22: =E100 -> -16
A23: Current Assets - Total | B23: 45033 | C23: 42351 | D23: 35947 | E23: 36229 | H23: +/-Discontinued Operations | I23: =B108 -> 615 | J23: =C108 -> 0 | K23: =D108 -> 0 | L23: =E108 -> 0
A24: Prop.Plant & Equip.- Total (Net) | B24: 6286 | C24: 6934 | D24: 7139 | E24: 6996 | H24: = Net Income | I24: =I21-I22+I23 -> 5563 | J24: =J21-J22+J23 -> 2442 | K24: =K21-K22+K23 -> 3211 | L24: =L21-L22+L23 -> 4592
A25: P.P.& E.- Total (Gross) | B25: 13177 | C25: 13817 | D25: 14324 | E25: 14756
A26: Deprec.Depl.& Amort. | B26: 6891 | C26: 6883 | D26: 7185 | E26: 7760
A27: Invest. & Advances - Eq.Meth. | B27: 0 | C27: 0 | D27: 0 | E27: 0 | H27: Income Statement Metrics
A28: Invest. & Advances - Other | B28: 8071 | C28: 7596 | D28: 7193 | E28: 7423 | H28: Gross Profit Margin | I28: =I6/I4 -> 0.24106446 | J28: =J6/J4 -> 0.24822827 | K28: =K6/K4 -> 0.26881538 | L28: =L6/L4 -> 0.25216864
A29: Intangibles | B29: 27903 | C29: 26817 | D29: 26047 | E29: 24731 | H29: Operating Margin Before D&A (EBITDA Margin) | I29: =I8/I4 -> 0.083787069 | J29: =J8/J4 -> 0.092628616 | K29: =K8/K4 -> 0.10374894 | L29: =L8/L4 -> 0.10519322
A30: Assets - Other | B30: 5442 | C30: 5913 | D30: 5763 | E30: 4367 | H30: Operating Margin After D&A (EBIT Margin) | I30: =I10/I4 -> 0.048736623 | J30: =J10/J4 -> 0.061778477 | K30: =K10/K4 -> 0.06639525 | L30: =L10/L4 -> 0.072514571
A31: Deferred Charges | B31: . | C31: . | D31: . | E31: . | H31: NOPAT Margin | I31: =I12/I4 -> 0.040664594 | J31: =J12/J4 -> 0.046396115 | K31: =K12/K4 -> 0.054574948 | L31: =L12/L4 -> 0.065734286
A32: Other Asst., Excl.Def.Chg. | B32: 5442 | C32: 5913 | D32: 5763 | E32: 4367 | H32: Pretax Margin | I32: =I19/I4 -> 0.058529403 | J32: =J19/J4 -> 0.031524619 | K32: =K19/K4 -> 0.043958157 | L32: =L19/L4 -> 0.052821581
A33: Assets - Total | B33: 92735 | C33: 89611 | D33: 82089 | E33: 79746 | H33: Net Profit Margin | I33: =I24/I4 -> 0.054971985 | J33: =J24/J4 -> 0.023870734 | K33: =K24/K4 -> 0.03631326 | L33: =L24/L4 -> 0.048050059
A34: LIABILITIES | H34: Effective Tax Rate | I34: =I11 -> 0.16562553 | J34: =J11 -> 0.24899225 | K34: =K11 -> 0.17802933 | L34: =L11 -> 0.093502377
A35: Debt in Current Liabilities | B35: 6110 | C35: 6833 | D35: 7235 | E35: 5440 | H35: Interest Coverage Ratio | I35: =I15/I16 -> 3.1984436 | J35: =J15/J16 -> 5.1718494 | K35: =K15/K16 -> 3.9113924 | L35: =L15/L16 -> 4.9713056
A36: Notes Payable | B36: 0 | C36: 0 | D36: 0 | E36: 0
A37: Debt - Due in One Year | B37: 6110 | C37: 6833 | D37: 7235 | E37: 5440
A38: Accounts Payable | B38: 27143 | C38: 18598 | D38: 19389 | E38: 20832 | H38: Balance Sheet | I38: Working Capital Accounts
A39: Income Taxes Payable | B39: . | C39: . | D39: . | E39: .
A40: Current Liabilities - Other | B40: 22966 | C40: 26223 | D40: 21870 | E40: 20255 | H40: ( - ) Accounts Receivables | I40: =B11 -> 18132 | J40: =C11 -> 18141 | K40: =D11 -> 13986 | L40: =E11 -> 15602
...

Sheet Dell_Cost-of-Capital
C1: 2024 Fiscal Year
A2: Step 1
A3: i | B3: risk free rate (5-year Treasury Yield | C3: 0.0372
A4: ii | B4: equity beta | C4: 1.09
A5: iii | B5: expected market risk premium | C5: 0.04
B6: cost of equity rE | C6: =C3+C4*C5 -> 0.0808 | D6: Required return demanded by common shareholders given market conditions and the stock’s systematic risk.
A8: Step 2 | B8: S&P's Credit Rating | C8: BBB
B9: debt beta | C9: 0.1
B10: cost of debt rD | C10: =C3+C9*C5 -> 0.0412 | D10: Required return demanded by lenders given market conditions and the company’s debt risk.
A12: Step 3.1
B13: Cash and Short-Term Investments | C13: ='Dell''s_Financial_Statements'!E8 -> 3756 | D13: USD million
B14: Debt in Current Liabilities | C14: ='Dell''s_Financial_Statements'!E35 -> 5440 | D14: USD million
B15: Long-Term Debt - Total | C15: ='Dell''s_Financial_Statements'!E44 -> 19885 | D15: USD million
B16: Net Debt | C16: =C15+C14-C13 -> 21569 | D16: USD million
A18: Step 3.2 | B18: Stock Price | C18: 103.6 | D18: USD million
B19: Shares Outstanding | C19: ='Dell''s_Financial_Statements'!E314 -> 696 | D19: millions
B20: Market Value of Equity | C20: =C19*C18 -> 72105.6 | D20: USD million
A21: Step 3.3 | B21: Enterprise Value | C21: =C20+C16 -> 93674.6 | D21: USD million
A23: Step 4 | B23: Tax rate | C23: 0.21
B24: WACC | C24: =C20/C21*C6+C16/C21*C10*(1-C23) -> 0.069689759
A28: rE weight | C28: =C20/C21 -> 0.76974548
A30: rD weight | C30: =C16/C21 -> 0.23025452
A32: WACC | C32: =C28*C6+C30*C10*(1-C23) -> 0.069689759

Sheet DCF_Dell
A1: NPV for Dell's New Tablet Computer
A3: Assumptions (Amounts in Millions Unless Otherwise Indicated)
A4: Initial Capital Expenditure (Year 0) | B4: ='Dell''s_Financial_Statements'!E25*0.06 -> 885.36 | C4: <-- 6% of Gross PPE at the end of last fiscal year = 6%*"P.P.& E.- Total (Gross)"
A5: Useful Life of Assets (in year) | B5: 5 | C5: <-- 5-year
A6: Annual Depreciation | B6: =B4/B5 -> 177.072 | C6: <-- Annual depreciation = (Purchase value -Salvage value)/useful life, where purchase value equals the initial capital expenditure, and salvage value = 0
A7: EBITDA/Sales profit margin | B7: ='Dell''s_Financial_Statements'!L29 -> 0.10519322 | C7: <-- The EBITDA/Sales profit margin in the last year = Operating Income Before Depreciation/Sales (Net)
A8: Net working capital in the last year | B8: ='Dell''s_Financial_Statements'!L46 -> 1486 | C8: <-- accounts receivable + inventory - accounts payable = "Receivables" + "Inventories - Total" - "Accounts Payable"
A9: Net working capital/Sales (Net) in the last year | B9: ='Dell''s_Financial_Statements'!L46/'Dell''s_Financial_Statements'!L4 -> 0.0155493 | C9: <-- Net working capital/Sales (Net)
A10: Initial Net Working Capital (Year 0) | B10: =C19*0.01 -> 57.3402 | C10: <-- 1% of project sales in Year 1
A11: Net Working Capital in Year 5 | B11: 0 | C11: <-- At the end of the project life (Year 5), you recover all the net working capital for the project. (E.g., sell all inventory, collect receivable, and pay the accounts payable.) Thus, The NWC level in Year 5 equals zero.
A12: Tax Rate | B12: 0.21
A13: Cost of Capital | B13: 0.0697
A14: Revenues in Year 1 | B14: ='Dell''s_Financial_Statements'!L4*0.06 -> 5734.02 | C14: <-- 6% of the company's total revenue in the last fiscal year = 6%* Sales (Net)
A15: Revenue Growth Rate per Year | D15: 0.1 | E15: 0.08 | F15: 0.03 | G15: 0.03
B16: Year | C16: Year | D16: Year | E16: Year | F16: Year | G16: Year
B17: 2025 | C17: =B17+1 -> 2026 | D17: =C17+1 -> 2027 | E17: =D17+1 -> 2028 | F17: =E17+1 -> 2029 | G17: =F17+1 -> 2030
A18: Unlevered Income Statements | B18: 0 | C18: 1 | D18: 2 | E18: 3 | F18: 4 | G18: 5
A19: Revenues | C19: =B14 -> 5734.02 | D19: =C19*(1+D15) -> 6307.422 | E19: =D19*(1+E15) -> 6812.0158 | F19: =E19*(1+F15) -> 7016.3762 | G19: =F19*(1+G15) -> 7226.8675
A20: EBITDA | C20: =$B$7*C19 -> 603.18 | D20: =$B$7*D19 -> 663.498 | E20: =$B$7*E19 -> 716.57784 | F20: =$B$7*F19 -> 738.07518 | G20: =$B$7*G19 -> 760.21743
A21: Depreciation | C21: =$B$6 -> 177.072 | D21: =$B$6 -> 177.072 | E21: =$B$6 -> 177.072 | F21: =$B$6 -> 177.072 | G21: =$B$6 -> 177.072
A22: Tax | C22: =(C20-C21)*$B$12 -> 89.48268 | D22: =(D20-D21)*$B$12 -> 102.14946 | E22: =(E20-E21)*$B$12 -> 113.29623 | F22: =(F20-F21)*$B$12 -> 117.81067 | G22: =(G20-G21)*$B$12 -> 122.46054
A23: Unlevered Net Income | C23: =(C20-C21)*(1-$B$12) -> 336.62532 | D23: =(D20-D21)*(1-$B$12) -> 384.27654 | E23: =(E20-E21)*(1-$B$12) -> 426.20961 | F23: =(F20-F21)*(1-$B$12) -> 443.19251 | G23: =(G20-G21)*(1-$B$12) -> 460.68489
A25: Working Capital Calculations
A26: NWC Level | B26: =B10 -> 57.3402 | C26: ='Dell''s_Financial_Statements'!$L$70*DCF_Dell!C19 -> 89.16 | D26: ='Dell''s_Financial_Statements'!$L$70*DCF_Dell!D19 -> 98.076 | E26: ='Dell''s_Financial_Statements'!$L$70*DCF_Dell!E19 -> 105.92208 | F26: ='Dell''s_Financial_Statements'!$L$70*DCF_Dell!F19 -> 109.09974 | G26: 0
A27: Change in NWC | C27: =C26-B26 -> 31.8198 | D27: =D26-C26 -> 8.916 | E27: =E26-D26 -> 7.84608 | F27: =F26-E26 -> 3.1776624 | G27: =G26-F26 -> -109.09974
A28: CF from Change in NWC | C28: =-C27 -> -31.8198 | D28: =-D27 -> -8.916 | E28: =-E27 -> -7.84608 | F28: =-F27 -> -3.1776624 | G28: =-G27 -> 109.09974
A30: Calculating Free Cash Flows
A31: Unlevered Net Income | C31: =C23 -> 336.62532 | D31: =D23 -> 384.27654 | E31: =E23 -> 426.20961 | F31: =F23 -> 443.19251 | G31: =G23 -> 460.68489
A32: Add Back Depreciation | C32: =C21 -> 177.072 | D32: =D21 -> 177.072 | E32: =E21 -> 177.072 | F32: =F21 -> 177.072 | G32: =G21 -> 177.072
A33: Subtract Change in NWC | C33: =C27 -> 31.8198 | D33: =D27 -> 8.916 | E33: =E27 -> 7.84608 | F33: =F27 -> 3.1776624 | G33: =G27 -> -109.09974
A34: Subtract Capital Expenditure | B34: =$B$4 -> 885.36 | C34: 0 | D34: 0 | E34: 0 | F34: 0 | G34: 0
A35: Free Cash Flow | B35: =-(B34+B26) -> -942.7002 | C35: =C31+C32-C34-C33 -> 481.87752 | D35: =D31+D32-D34-D33 -> 552.43254 | E35: =E31+E32-E34-E33 -> 595.43553 | F35: =F31+F32-F34-F33 -> 617.08685 | G35: =G31+G32-G34-G33 -> 746.85663
A37: Discount Factor (1/(1+r)^n) | B37: =(1/(1+$B$13)^B18) -> 1 | C37: =(1/(1+$B$13)^C18) -> 0.93484154 | D37: =(1/(1+$B$13)^D18) -> 0.87392871 | E37: =(1/(1+$B$13)^E18) -> 0.81698487 | F37: =(1/(1+$B$13)^F18) -> 0.7637514 | G37: =(1/(1+$B$13)^G18) -> 0.71398653
A38: PV(FCF) | B38: =B37*B35 -> -942.7002 | C38: =C37*C35 -> 450.47912 | D38: =D37*D35 -> 482.78666 | E38: =E37*E35 -> 486.46182 | F38: =F37*F35 -> 471.30094 | G38: =G37*G35 -> 533.24558
A39: NPV | B39: =B35+NPV(B13,C35,D35,E35,F35,G35) -> 1481.5739

Sheet Microsoft_Financial_Statements
A1: Financial Statement for: MICROSOFT CORP | B1: 2021 | C1: 2022 | D1: 2023 | E1: 2024 | I1: 2021 | J1: 2022 | K1: 2023 | L1: 2024
A2: Fiscal Years: 2021 to 2024 | H2: Income Statement
H3: Revenues | I3: =B73 -> 168088 | J3: =C73 -> 198270 | K3: =D73 -> 211915 | L3: =E73 -> 245122
H4: - COGS | I4: =B74 -> 41332 | J4: =C74 -> 48050 | K4: =D74 -> 52211 | L4: =E74 -> 54114
A5: BALANCE SHEET | H5: = Gross Profit | I5: =I3-I4 -> 126756 | J5: =J3-J4 -> 150220 | K5: =K3-K4 -> 159704 | L5: =L3-L4 -> 191008
A6: ASSETS | H6: - SG&A | I6: =B75 -> 45940 | J6: =C75 -> 52111 | K6: =D75 -> 56510 | L6: =E75 -> 61575
A7: Cash and Short-Term Investments | B7: 130334 | C7: 104757 | D7: 111262 | E7: 75543 | H7: = EBITDA / Operating Income before D&A | I7: =I5-I6 -> 80816 | J7: =J5-J6 -> 98109 | K7: =K5-K6 -> 103194 | L7: =L5-L6 -> 129433
A8: Cash | B8: 14224 | C8: 13931 | D8: 34704 | E8: 18315 | H8: - Depreciation & Amortization | I8: =B77 -> 10900 | J8: =C77 -> 14600 | K8: =D77 -> 13500 | L8: =E77 -> 20000
A9: Short-Term Investments | B9: 116110 | C9: 90826 | D9: 76558 | E9: 57228 | H9: = EBIT/ Operating Income | I9: =I7-I8 -> 69916 | J9: =J7-J8 -> 83509 | K9: =K7-K8 -> 89694 | L9: =L7-L8 -> 109433
A10: Receivables | B10: 38043 | C10: 50361 | D10: 57888 | E10: 67424 | H10: EFF Tax Rate | I10: =I19/I18 -> 0.13826615 | J10: =J19/J18 -> 0.13113383 | K10: =K19/K18 -> 0.18978625 | L10: =L19/L18 -> 0.18231327
A11: Receivables - Trade | B11: 38043 | C11: 44261 | D11: 48688 | E11: 56924 | H11: = NOPAT | I11: =I9*(1-I10) -> 60248.984 | J11: =J9*(1-J10) -> 72558.145 | K11: =K9*(1-K10) -> 72671.312 | L11: =L9*(1-L10) -> 89481.912
A12: Income Tax Refund | B12: 0 | C12: 0 | D12: 0 | E12: 0
A13: Current Receivables - Other | B13: 0 | C13: 6100 | D13: 9200 | E13: 10500
A14: Inventories - Total | B14: 2636 | C14: 3742 | D14: 2500 | E14: 1246 | H14: EBIT/ Operating Income | I14: =I9 -> 69916 | J14: =J9 -> 83509 | K14: =K9 -> 89694 | L14: =L9 -> 109433
A15: Inventories - Raw Materials | B15: 1190 | C15: 1144 | D15: 709 | E15: 394 | H15: - Interest Expense | I15: =B82 -> 2330 | J15: =C82 -> 2047 | K15: =D82 -> 1995 | L15: =E82 -> 2983
A16: Inventories - Work in Process | B16: 79 | C16: 82 | D16: 23 | E16: 7 | H16: +/- Nonoperating Income (Expense) | I16: =B83 -> 3516 | J16: =C83 -> 2380 | K16: =D83 -> 2783 | L16: =E83 -> 1337
A17: Inventories - Finished Goods | B17: 1367 | C17: 2516 | D17: 1768 | E17: 845 | H17: +/- Special Items | I17: 0 | J17: =C86 -> -126 | K17: =D86 -> -1171 | L17: =E86 -> 0
A18: Inventories - Other | B18: 0 | C18: 0 | D18: 0 | E18: 0 | H18: =Pretax Income | I18: =I14-I15+I16+I17 -> 71102 | J18: =J14-J15+J16+J17 -> 83716 | K18: =K14-K15+K16+K17 -> 89311 | L18: =L14-L15+L16+L17 -> 107787
A19: Current Assets - Other | B19: 13393 | C19: 10824 | D19: 12607 | E19: 15521 | H19: - Income Taxes | I19: =B90 -> 9831 | J19: =C90 -> 10978 | K19: =D90 -> 16950 | L19: =E90 -> 19651
A20: Prepaid Expense | B20: 0 | C20: 0 | D20: 0 | E20: 0 | H20: = Income Before Extradoniary Items | I20: =I18-I19 -> 61271 | J20: =J18-J19 -> 72738 | K20: =K18-K19 -> 72361 | L20: =L18-L19 -> 88136
A21: Other Curr.Asst, Excl.Ppd.Exp. | B21: 13393 | C21: 10824 | D21: 12607 | E21: 15521 | H21: -Minority Interest | I21: =B99 -> 0 | J21: =C99 -> 0 | K21: =D99 -> 0 | L21: =E99 -> 0
A22: Current Assets - Total | B22: 184406 | C22: 169684 | D22: 184257 | E22: 159734 | H22: +/-Discontinued Operations | I22: =B107 -> 0 | J22: =C107 -> 0 | K22: =D107 -> 0 | L22: =E107 -> 0
A23: Prop.Plant & Equip.- Total (Net) | B23: 70803 | C23: 87546 | D23: 109987 | E23: 154552 | H23: = Net Income | I23: =I20-I21+I22 -> 61271 | J23: =J20-J21+J22 -> 72738 | K23: =K20-K21+K22 -> 72361 | L23: =L20-L21+L22 -> 88136
A24: P.P.& E.- Total (Gross) | B24: 122154 | C24: 147206 | D24: 178238 | E24: 230973
A25: Deprec.Depl.& Amort. | B25: 51351 | C25: 59660 | D25: 68251 | E25: 76421
A26: Invest. & Advances - Eq.Meth. | B26: . | C26: . | D26: . | E26: 6000 | H26: Income Statement Metrics
A27: Invest. & Advances - Other | B27: 9384 | C27: 10691 | D27: 14379 | E27: 13500 | H27: Gross Profit Margin | I27: =I5/I3 -> 0.75410499 | J27: =J5/J3 -> 0.7576537 | K27: =K5/K3 -> 0.75362291 | L27: =L5/L3 -> 0.77923646
A28: Intangibles | B28: 57511 | C28: 78822 | D28: 77252 | E28: 146817 | H28: Operating Margin Before D&A (EBITDA Margin) | I28: =I7/I3 -> 0.48079577 | J28: =J7/J3 -> 0.49482524 | K28: =K7/K3 -> 0.48695939 | L28: =L7/L3 -> 0.52803502
A29: Assets - Other | B29: 11675 | C29: 18097 | D29: 26101 | E29: 31560 | H29: Operating Margin (EBIT Margin) | I29: =I9/I3 -> 0.41594879 | J29: =J9/J3 -> 0.42118828 | K29: =K9/K3 -> 0.42325461 | L29: =L9/L3 -> 0.446443
A30: Deferred Charges | B30: 0 | C30: 0 | D30: 0 | E30: 0 | H30: NOPAT Margin | I30: =I11/I3 -> 0.35843715 | J30: =J11/J3 -> 0.36595625 | K30: =K11/K3 -> 0.3429267 | L30: =L11/L3 -> 0.36505052
A31: Other Asst., Excl.Def.Chg. | B31: 11675 | C31: 18097 | D31: 26101 | E31: 31560 | H31: Pretax Margin | I31: =I18/I3 -> 0.42300462 | J31: =J18/J3 -> 0.42223231 | K31: =K18/K3 -> 0.42144728 | L31: =L18/L3 -> 0.43972797
A32: Assets - Total | B32: 333779 | C32: 364840 | D32: 411976 | E32: 512163 | H32: Net Profit Margin | I32: =I23/I3 -> 0.3645174 | J32: =J23/J3 -> 0.36686337 | K32: =K23/K3 -> 0.34146238 | L32: =L23/L3 -> 0.35955973
A33: LIABILITIES | H33: Effective Tax Rate | I33: =I10 -> 0.13826615 | J33: =J10 -> 0.13113383 | K33: =K10 -> 0.18978625 | L33: =L10 -> 0.18231327
A34: Debt in Current Liabilities | B34: 10825 | C34: 6037 | D34: 8853 | E34: 14871 | H34: Interest Coverage Ratio | I34: =I14/I15 -> 30.006867 | J34: =J14/J15 -> 40.795799 | K34: =K14/K15 -> 44.959398 | L34: =L14/L15 -> 36.685551
A35: Notes Payable | B35: 0 | C35: 0 | D35: 0 | E35: 6693
A36: Debt - Due in One Year | B36: 10825 | C36: 6037 | D36: 8853 | E36: 8178
A37: Accounts Payable | B37: 15163 | C37: 19000 | D37: 18095 | E37: 21996 | H37: Balance Sheet | I37: Working Capital Accounts
A38: Income Taxes Payable | B38: 2174 | C38: 4067 | D38: 4152 | E38: 5017
A39: Current Liabilities - Other | B39: 60495 | C39: 65978 | D39: 73049 | E39: 83402 | H39: ( - ) Accounts Receivables | I39: =B10 -> 38043 | J39: =C10 -> 50361 | K39: =D10 -> 57888 | L39: =E10 -> 67424
A40: Accrued Expense | B40: 10057 | C40: 10661 | D40: 11009 | E40: 12564 | H40: ∆ Cash from A/R | J40: =I39-J39 -> -12318 | K40: =J39-K39 -> -7527 | L40: =K39-L39 -> -9536
...

Sheet MSFT_Cost-of-Capital
C1: 2024 Fiscal Year
A2: Step 1
A3: i | B3: risk free rate (5-year Treasury Yield | C3: 0.0372
A4: ii | B4: equity beta | C4: 1.07
A5: iii | B5: expected market risk premium | C5: 0.04
B6: cost of equity rE | C6: =C3+C4*C5 -> 0.08 | D6: Required return demanded by common shareholders given market conditions and the stock’s systematic risk.
A8: Step 2 | B8: S&P's Credit Rating | C8: AAA
B9: debt beta | C9: 0.05
B10: cost of debt rD | C10: =C3+C9*C5 -> 0.0392 | D10: Required return demanded by lenders given market conditions and the company’s debt risk.
A12: Step 3.1
B13: Cash and Short-Term Investments | C13: =Microsoft_Financial_Statements!E7 -> 75543 | D13: USD million
B14: Debt in Current Liabilities | C14: =Microsoft_Financial_Statements!E34 -> 14871 | D14: USD million
B15: Long-Term Debt - Total | C15: =Microsoft_Financial_Statements!E43 -> 82981 | D15: USD million
B16: Net Debt | C16: =C15+C14-C13 -> 22309 | D16: USD million
A18: Step 3.2 | B18: Stock Price | C18: 415 | D18: USD million
B19: Shares Outstanding | C19: =Microsoft_Financial_Statements!E313 -> 7434 | D19: millions
B20: Market Value of Equity | C20: =C19*C18 -> 3085110 | D20: USD million
A21: Step 3.3 | B21: Enterprise Value | C21: =C20+C16 -> 3107419 | D21: USD million
A23: Step 4 | B23: Tax rate | C23: 0.21
B24: WACC | C24: =C20/C21*C6+C16/C21*C10*(1-C23) -> 0.079647986
A28: rE weight | C28: =C20/C21 -> 0.99282073
A30: rD weight | C30: =C16/C21 -> 0.00717927
A32: WACC | C32: =C28*C6+C30*C10*(1-C23) -> 0.079647986

Sheet DCF_Microsoft
A1: NPV for Microsoft's Project
A3: Assumptions (Amounts in Millions Unless Otherwise Indicated)
A4: Initial Capital Expenditure (Year 0) | B4: 13855 | C4: Based on research that was conducted and real-world analogs, a total project cost of ≈ $14 billion
A5: Useful Life of Assets (in year) | B5: 5 | C5: <-- 5-year
A6: Annual Depreciation | B6: =B4/B5 -> 2771 | C6: <-- Annual depreciation = (Purchase value -Salvage value)/useful life, where purchase value equals the initial capital expenditure, and salvage value = 0
A7: EBITDA/Sales profit margin | B7: =Microsoft_Financial_Statements!L28 -> 0.52803502 | C7: <-- The EBITDA/Sales profit margin in the last year = Operating Income Before Depreciation/Sales (Net)
A8: Net working capital in the last year | B8: =Microsoft_Financial_Statements!L45 -> 46674 | C8: <-- accounts receivable + inventory - accounts payable = "Receivables" + "Inventories - Total" - "Accounts Payable"
A9: Net working capital/Sales (Net) in the last year | B9: =Microsoft_Financial_Statements!L69 -> 0.19041131 | C9: <-- Net working capital/Sales (Net)
A10: Initial Net Working Capital (Year 0) | B10: =0.01*C19 -> 147.0732 | C10: <-- 1% of project sales in Year 1
A11: Net Working Capital in Year 5 | B11: 0 | C11: <-- At the end of the project life (Year 5), you recover all the net working capital for the project. (E.g., sell all inventory, collect receivable, and pay the accounts payable.) Thus, The NWC level in Year 5 equals zero.
A12: Tax Rate | B12: 0.21
A13: Cost of Capital | B13: 0.0796
A14: Revenues in Year 1 | B14: =Microsoft_Financial_Statements!L3*0.06 -> 14707.32 | C14: <-- 6% of the company's total revenue in the last fiscal year = 6%* Sales (Net)
A15: Revenue Growth Rate per Year | C15: 0.06 | D15: 0.15 | E15: 0.14 | F15: 0.1 | G15: 0.06
B16: Year | C16: Year | D16: Year | E16: Year | F16: Year | G16: Year
B17: =DCF_Dell!B17 -> 2025 | C17: =B17+1 -> 2026 | D17: =C17+1 -> 2027 | E17: =D17+1 -> 2028 | F17: =E17+1 -> 2029 | G17: =F17+1 -> 2030
A18: Unlevered Income Statements | B18: 0 | C18: 1 | D18: 2 | E18: 3 | F18: 4 | G18: 5
A19: Revenues | C19: =B14 -> 14707.32 | D19: =C19*(1+D15) -> 16913.418 | E19: =D19*(1+E15) -> 19281.297 | F19: =E19*(1+F15) -> 21209.426 | G19: =F19*(1+G15) -> 22481.992
A20: EBITDA | C20: =C19*$B$7 -> 7765.98 | D20: =D19*$B$7 -> 8930.877 | E20: =E19*$B$7 -> 10181.2 | F20: =F19*$B$7 -> 11199.32 | G20: =G19*$B$7 -> 11871.279
A21: Depreciation | C21: =B6 -> 2771 | D21: =C21 -> 2771 | E21: =D21 -> 2771 | F21: =E21 -> 2771 | G21: =F21 -> 2771
A22: Tax | C22: =(C20-C21)*$B$12 -> 1048.9458 | D22: =(D20-D21)*$B$12 -> 1293.5742 | E22: =(E20-E21)*$B$12 -> 1556.142 | F22: =(F20-F21)*$B$12 -> 1769.9471 | G22: =(G20-G21)*$B$12 -> 1911.0586
A23: Unlevered Net Income | C23: =(C20-C21)*(1-$B$12) -> 3946.0342 | D23: =(D20-D21)*(1-$B$12) -> 4866.3028 | E23: =(E20-E21)*(1-$B$12) -> 5854.0578 | F23: =(F20-F21)*(1-$B$12) -> 6658.3726 | G23: =(G20-G21)*(1-$B$12) -> 7189.2204
A25: Working Capital Calculations
A26: NWC Level | B26: =B10 -> 147.0732 | C26: =C19*$B$9 -> 2800.44 | D26: =D19*$B$9 -> 3220.506 | E26: =E19*$B$9 -> 3671.3768 | F26: =F19*$B$9 -> 4038.5145 | G26: 0
A27: Change in NWC | C27: =C26-B26 -> 2653.3668 | D27: =D26-C26 -> 420.066 | E27: =E26-D26 -> 450.87084 | F27: =F26-E26 -> 367.13768 | G27: =G26-F26 -> -4038.5145
A28: CF from Change in NWC | C28: =-C27 -> -2653.3668 | D28: =-D27 -> -420.066 | E28: =-E27 -> -450.87084 | F28: =-F27 -> -367.13768 | G28: =-G27 -> 4038.5145
A30: Calculating Free Cash Flows
A31: Unlevered Net Income | C31: =(C20-C21)*(1-$B$12) -> 3946.0342 | D31: =(D20-D21)*(1-$B$12) -> 4866.3028 | E31: =(E20-E21)*(1-$B$12) -> 5854.0578 | F31: =(F20-F21)*(1-$B$12) -> 6658.3726 | G31: =(G20-G21)*(1-$B$12) -> 7189.2204
A32: Add Back Depreciation | C32: =C21 -> 2771 | D32: =D21 -> 2771 | E32: =E21 -> 2771 | F32: =F21 -> 2771 | G32: =G21 -> 2771
A33: Subtract Change in NWC | C33: =C27 -> 2653.3668 | D33: =D27 -> 420.066 | E33: =E27 -> 450.87084 | F33: =F27 -> 367.13768 | G33: =G27 -> -4038.5145
A34: Subtract Capital Expenditure | B34: =B4 -> 13855 | C34: 0 | D34: 0 | E34: 0 | F34: 0 | G34: 0
A35: Free Cash Flow | B35: =-(B34+B26) -> -14002.073 | C35: =C31+C32-C33-C34 -> 4063.6674 | D35: =D31+D32-D33-D34 -> 7217.2368 | E35: =E31+E32-E33-E34 -> 8174.187 | F35: =F31+F32-F33-F34 -> 9062.2349 | G35: =G31+G32-G33-G34 -> 13998.735
A37: Discount Factor (1/(1+r)^n) | B37: =(1/(1+$B$13)^B18) -> 1 | C37: =(1/(1+$B$13)^C18) -> 0.92626899 | D37: =(1/(1+$B$13)^D18) -> 0.85797424 | E37: =(1/(1+$B$13)^E18) -> 0.79471493 | F37: =(1/(1+$B$13)^F18) -> 0.73611979 | G37: =(1/(1+$B$13)^G18) -> 0.68184494
A38: PV(FCF) | B38: =B35*B37 -> -14002.073 | C38: =C35*C37 -> 3764.0491 | D38: =D35*D37 -> 6192.2033 | E38: =E35*E37 -> 6496.1484 | F38: =F35*F37 -> 6670.8905 | G38: =G35*G37 -> 9544.9665
A39: NPV | B39: =B35+NPV(B13,C35,D35,E35,F35,G35) -> 18666.185
